<robot name="onshape">
<link name="base">
<visual>
<origin xyz="-1.5593838454278832195 1.9090129831169491137 -0.29396907470682126506" rpy="-0.016779379681320233386 -0.085219101190160934101 0.085260403508846671627" />
<geometry>
<mesh filename="package:///desk.stl"/>
</geometry>
<material name="desk_material">
<color rgba="0.97254901960784312376 0.52941176470588235947 0.0039215686274509803377 1.0"/>
</material>
</visual>
<collision>
<origin xyz="-1.5593838454278832195 1.9090129831169491137 -0.29396907470682126506" rpy="-0.016779379681320233386 -0.085219101190160934101 0.085260403508846671627" />
<geometry>
<mesh filename="package:///desk.stl"/>
</geometry>
</collision>
<visual>
<origin xyz="-1.5572972321637943427 1.9087837987025517705 -0.31807785981910458029" rpy="-0.016779379681317919265 -0.085219101190171425708 0.085260403508848989218" />
<geometry>
<mesh filename="package:///base.stl"/>
</geometry>
<material name="base_material">
<color rgba="0.61568627450980395466 0.81176470588235294379 0.92941176470588238168 1.0"/>
</material>
</visual>
<collision>
<origin xyz="-1.5572972321637943427 1.9087837987025517705 -0.31807785981910458029" rpy="-0.016779379681317919265 -0.085219101190171425708 0.085260403508848989218" />
<geometry>
<mesh filename="package:///base.stl"/>
</geometry>
</collision>
<inertial>
<origin xyz="-1.55890595374126395 1.9172705516825521155 -0.31405119278813919959" rpy="0 0 0"/>
<mass value="2783.0098340160834596" />
<inertia ixx="1203.964315874042768" ixy="-207.64169845183550933"  ixz="-306.91779405858983409" iyy="3596.1879992802146262" iyz="-6.7844617226970331814" izz="4746.4066586307535545" />
</inertial>
</link>

<link name="pof-1">
<visual>
<origin xyz="0 -1.1102230246251565404e-16 0.12587510831897211205" rpy="-3.141592653589793116 7.3063622205014325898e-18 8.0357969773507134401e-17" />
<geometry>
<mesh filename="package:///pof-1.stl"/>
</geometry>
<material name="pof-1_material">
<color rgba="1 0 0 1.0"/>
</material>
</visual>
<collision>
<origin xyz="0 -1.1102230246251565404e-16 0.12587510831897211205" rpy="-3.141592653589793116 7.3063622205014325898e-18 8.0357969773507134401e-17" />
<geometry>
<mesh filename="package:///pof-1.stl"/>
</geometry>
</collision>
<inertial>
<origin xyz="-5.3794119374101119491e-05 0.013657888947206342847 0.020100338512034021665" rpy="0 0 0"/>
<mass value="18.461651320620415362" />
<inertia ixx="0.11921429049705742353" ixy="-4.8423809114056686246e-05"  ixz="-4.481177413355389962e-05" iyy="0.1224913184324893517" iyz="0.015453311881334093336" izz="0.13493609659557595504" />
</inertial>
</link>

<link name="pof-2">
<visual>
<origin xyz="0.0015635189626288280643 -0.18788436859521207012 0.050199999999999800337" rpy="-1.570796326794896558 2.6628957043203044469e-18 -1.1234257958382827205e-18" />
<geometry>
<mesh filename="package:///pof-2.stl"/>
</geometry>
<material name="pof-2_material">
<color rgba="0.2313725490196078538 0.38039215686274507888 0.7058823529411765163 1.0"/>
</material>
</visual>
<collision>
<origin xyz="0.0015635189626288280643 -0.18788436859521207012 0.050199999999999800337" rpy="-1.570796326794896558 2.6628957043203044469e-18 -1.1234257958382827205e-18" />
<geometry>
<mesh filename="package:///pof-2.stl"/>
</geometry>
</collision>
<inertial>
<origin xyz="-0.0016816311991630561104 0.36539027539729523886 0.050185690788443447496" rpy="0 0 0"/>
<mass value="90.792995568270370654" />
<inertia ixx="4.080533566788099975" ixy="-0.014107936134092060113"  ixz="-0.00093094549926676906614" iyy="0.69445745640086908868" iyz="-0.17175852278019101971" izz="4.0820424441943217175" />
</inertial>
</link>

<link name="pof-3">
<visual>
<origin xyz="-0.00025152001946926461073 -0.91352102952272762337 0.081700000000000327915" rpy="-1.570796326794896558 6.0013402389982504024e-17 8.9982465364959318249e-18" />
<geometry>
<mesh filename="package:///pof-3.stl"/>
</geometry>
<material name="pof-3_material">
<color rgba="0.97254901960784312376 0.52941176470588235947 0.0039215686274509803377 1.0"/>
</material>
</visual>
<collision>
<origin xyz="-0.00025152001946926461073 -0.91352102952272762337 0.081700000000000327915" rpy="-1.570796326794896558 6.0013402389982504024e-17 8.9982465364959318249e-18" />
<geometry>
<mesh filename="package:///pof-3.stl"/>
</geometry>
</collision>
<inertial>
<origin xyz="-0.0015017590816212833798 0.36493158135550518573 0.057706429112584084473" rpy="0 0 0"/>
<mass value="90.758536223851280056" />
<inertia ixx="4.0758784147755813265" ixy="-0.01394864874177461668"  ixz="-0.00094375868821803046965" iyy="0.69434683899541416174" iyz="-0.17088798621275941292" izz="4.0774824929406010554" />
</inertial>
</link>

<link name="clip">
<visual>
<origin xyz="-0.00047798664432718851458 -1.6381767353871841131 0.085999999999999854339" rpy="-1.570796326794896558 4.1816874776645475849e-17 6.0950888174058542055e-17" />
<geometry>
<mesh filename="package:///clip.stl"/>
</geometry>
<material name="clip_material">
<color rgba="0.68235294117647060652 0.33333333333333331483 0.73725490196078435901 1.0"/>
</material>
</visual>
<collision>
<origin xyz="-0.00047798664432718851458 -1.6381767353871841131 0.085999999999999854339" rpy="-1.570796326794896558 4.1816874776645475849e-17 6.0950888174058542055e-17" />
<geometry>
<mesh filename="package:///clip.stl"/>
</geometry>
</collision>
<inertial>
<origin xyz="-0.001913858815135883757 0.11642970247119489857 0.046917912802365090152" rpy="0 0 0"/>
<mass value="22.331479230407797587" />
<inertia ixx="0.25374745793333286503" ixy="-0.0011777224488831610806"  ixz="-7.2510074599881998883e-05" iyy="0.15574754924953240764" iyz="-0.023869671179131034949" izz="0.23094535945716962444" />
</inertial>
</link>

<joint name="4" type="revolute">
<origin xyz="0.00022646662485747981464 0.72465570586445660073 -0.00029999999999796855832" rpy="5.137361735786234792e-15 -1.0945486962645612333e-14 0.19798616694489631906" />
<parent link="pof-3" />
<child link="clip" />
<axis xyz="0 0 1"/>
<limit effort="1" velocity="20" />
<joint_properties friction="0.0"/>
</joint>

<joint name="3" type="revolute">
<origin xyz="0.0018150389820983394394 0.72563666092751599734 -0.007499999999998063771" rpy="-5.389486419185938728e-15 -2.4171481691896483306e-15 -1.4423307164219771881" />
<parent link="pof-2" />
<child link="pof-3" />
<axis xyz="0 0 1"/>
<limit effort="1" velocity="20" />
<joint_properties friction="0.0"/>
</joint>

<joint name="2" type="revolute">
<origin xyz="-0.0015635189626301837507 -0.050200000000000466471 -0.062009260276239201726" rpy="-1.5707963267948970021 1.5590165419407260305 2.6631823367382545074e-13" />
<parent link="pof-1" />
<child link="pof-2" />
<axis xyz="0 0 1"/>
<limit effort="1" velocity="20" />
<joint_properties friction="0.0"/>
</joint>

<joint name="1" type="revolute">
<origin xyz="-1.5681506483058191836 1.909975890148307931 -0.19267720124688633709" rpy="-3.1098967673158242064 -0.080874737192539070119 -0.4833972803680686714" />
<parent link="base" />
<child link="pof-1" />
<axis xyz="0 0 1"/>
<limit effort="1" velocity="20" />
<joint_properties friction="0.0"/>
</joint>


</robot>
